<?xml version="1.0" encoding="utf-8"?>
<!-- This URDF was automatically created by SolidWorks to URDF Exporter! Originally created by Stephen Brawner (brawner@gmail.com) 
     Commit Version: 1.6.0-4-g7f85cfe  Build Version: 1.6.7995.38578
     For more information, please see http://wiki.ros.org/sw_urdf_exporter -->
<robot
  name="Assem1">
  <link
    name="base_link">
    <inertial>
      <origin
        xyz="0.121046763477735 0.151940637456914 0.285837338943906"
        rpy="0 0 0" />
      <mass
        value="5.51043299491621" />
      <inertia
        ixx="0.0325325116702204"
        ixy="1.36727792214883E-18"
        ixz="-5.77203012524323E-17"
        iyy="0.0589048225198257"
        iyz="5.94475935131385E-18"
        izz="0.0325325116702204" />
    </inertial>
    <visual>
      <origin
        xyz="0 0 0"
        rpy="0 0 0" />
      <geometry>
        <mesh
          filename="package://arm/meshes/base_link.STL" />
      </geometry>
      <material
        name="">
        <color
          rgba="0.6 0.6 0.6 1" />
      </material>
    </visual>
    <collision>
      <origin
        xyz="0 0 0"
        rpy="0 0 0" />
      <geometry>
        <mesh
          filename="package://arm/meshes/base_link.STL" />
      </geometry>
    </collision>
  </link>
  <link
    name="link1">
    <inertial>
      <origin
        xyz="-0.0563146043567339 0.0813964891053229 0.00239652329908495"
        rpy="0 0 0" />
      <mass
        value="2.25493350096987" />
      <inertia
        ixx="0.0116076379162407"
        ixy="0.00887971484912355"
        ixz="0.000401686650627847"
        iyy="0.0158798756899825"
        iyz="-0.000351049380153973"
        izz="0.0231563669188204" />
    </inertial>
    <visual>
      <origin
        xyz="0 0 0"
        rpy="0 0 0" />
      <geometry>
        <mesh
          filename="package://arm/meshes/link1.STL" />
      </geometry>
      <material
        name="">
        <color
          rgba="0.666666666666667 0.698039215686274 0.768627450980392 1" />
      </material>
    </visual>
    <collision>
      <origin
        xyz="0 0 0"
        rpy="0 0 0" />
      <geometry>
        <mesh
          filename="package://arm/meshes/link1.STL" />
      </geometry>
    </collision>
  </link>
  <joint
    name="joint1"
    type="fixed">
    <origin
      xyz="0.121046763477735 -0.285837338943906 0.197313597546825"
      rpy="1.5707963267949 0 -1.38459586714431" />
    <parent
      link="base_link" />
    <child
      link="link1" />
    <axis
      xyz="0 0 0" />
  </joint>
  <link
    name="link2">
    <inertial>
      <origin
        xyz="-0.142663403156673 0.0152228198054035 0.00806018930312294"
        rpy="0 0 0" />
      <mass
        value="0.920710305299373" />
      <inertia
        ixx="0.000614866050162195"
        ixy="-7.16287521655013E-05"
        ixz="0.000152423141181317"
        iyy="0.0182052989184288"
        iyz="3.03742949148828E-05"
        izz="0.0178613022406908" />
    </inertial>
    <visual>
      <origin
        xyz="0 0 0"
        rpy="0 0 0" />
      <geometry>
        <mesh
          filename="package://arm/meshes/link2.STL" />
      </geometry>
      <material
        name="">
        <color
          rgba="0.898039215686275 0.898039215686275 0.898039215686275 1" />
      </material>
    </visual>
    <collision>
      <origin
        xyz="0 0 0"
        rpy="0 0 0" />
      <geometry>
        <mesh
          filename="package://arm/meshes/link2.STL" />
      </geometry>
    </collision>
  </link>
  <joint
    name="joint2"
    type="revolute">
    <origin
      xyz="-0.150000000000001 0.16 -0.02"
      rpy="-1.5707963267949 0 -2.38897231765684" />
    <parent
      link="link1" />
    <child
      link="link2" />
    <axis
      xyz="0 0 0" />
  </joint>
  <link
    name="link3">
    <inertial>
      <origin
        xyz="0.00538331055455715 -0.00508437353022007 0.00146278329110827"
        rpy="0 0 0" />
      <mass
        value="1.43146260772506" />
      <inertia
        ixx="0.00186636966001071"
        ixy="0.000324747623278668"
        ixz="-9.34132533564527E-05"
        iyy="0.00807676440931879"
        iyz="0.000112858949971255"
        izz="0.00844554646583347" />
    </inertial>
    <visual>
      <origin
        xyz="0 0 0"
        rpy="0 0 0" />
      <geometry>
        <mesh
          filename="package://arm/meshes/link3.STL" />
      </geometry>
      <material
        name="">
        <color
          rgba="0.666666666666667 0.698039215686274 0.768627450980392 1" />
      </material>
    </visual>
    <collision>
      <origin
        xyz="0 0 0"
        rpy="0 0 0" />
      <geometry>
        <mesh
          filename="package://arm/meshes/link3.STL" />
      </geometry>
    </collision>
  </link>
  <joint
    name="joint3"
    type="revolute">
    <origin
      xyz="-0.290305042882929 -0.0475000000000003 -0.0310082584933766"
      rpy="1.5707963267949 -1.21189757589006 3.14159265358979" />
    <parent
      link="link2" />
    <child
      link="link3" />
    <axis
      xyz="0 0 0" />
  </joint>
  <link
    name="link4">
    <inertial>
      <origin
        xyz="-0.0659648913117669 -4.8796078289115E-10 -1.10951992038366E-09"
        rpy="0 0 0" />
      <mass
        value="0.581435304453433" />
      <inertia
        ixx="0.00059652401434061"
        ixy="-1.05373364791802E-11"
        ixz="-3.09919140792868E-11"
        iyy="0.00158017073492887"
        iyz="-2.36731285067199E-10"
        izz="0.00140634607897422" />
    </inertial>
    <visual>
      <origin
        xyz="0 0 0"
        rpy="0 0 0" />
      <geometry>
        <mesh
          filename="package://arm/meshes/link4.STL" />
      </geometry>
      <material
        name="">
        <color
          rgba="0.792156862745098 0.819607843137255 0.933333333333333 1" />
      </material>
    </visual>
    <collision>
      <origin
        xyz="0 0 0"
        rpy="0 0 0" />
      <geometry>
        <mesh
          filename="package://arm/meshes/link4.STL" />
      </geometry>
    </collision>
  </link>
  <joint
    name="joint4"
    type="continuous">
    <origin
      xyz="-0.200999999999998 0 0"
      rpy="-3.10243696229549 0 0" />
    <parent
      link="link3" />
    <child
      link="link4" />
    <axis
      xyz="0 0 0" />
  </joint>
  <link
    name="link5">
    <inertial>
      <origin
        xyz="-0.000178318239085762 -1.11022302462516E-16 0.0169618551287792"
        rpy="0 0 0" />
      <mass
        value="0.339144547925523" />
      <inertia
        ixx="0.000358769992191287"
        ixy="2.03287907341032E-20"
        ixz="-3.56575702010588E-06"
        iyy="0.000355541202477726"
        iyz="2.77826806699411E-19"
        izz="0.000248853470602005" />
    </inertial>
    <visual>
      <origin
        xyz="0 0 0"
        rpy="0 0 0" />
      <geometry>
        <mesh
          filename="package://arm/meshes/link5.STL" />
      </geometry>
      <material
        name="">
        <color
          rgba="0.666666666666667 0.698039215686274 0.768627450980392 1" />
      </material>
    </visual>
    <collision>
      <origin
        xyz="0 0 0"
        rpy="0 0 0" />
      <geometry>
        <mesh
          filename="package://arm/meshes/link5.STL" />
      </geometry>
    </collision>
  </link>
  <joint
    name="joint5"
    type="continuous">
    <origin
      xyz="-0.127684604956799 -0.0380953376087066 -0.000499999999999598"
      rpy="2.00541220615079 -1.5707963267949 0" />
    <parent
      link="link4" />
    <child
      link="link5" />
    <axis
      xyz="0 0 0" />
  </joint>
  <link
    name="link6">
    <inertial>
      <origin
        xyz="-0.0062847062070423 1.11022302462516E-16 0"
        rpy="0 0 0" />
      <mass
        value="0.0762574810565131" />
      <inertia
        ixx="3.99525744954328E-05"
        ixy="-6.7762635780344E-21"
        ixz="-2.15993401549847E-20"
        iyy="3.7955979870062E-05"
        iyz="-3.59989002583078E-21"
        izz="3.20288004196063E-05" />
    </inertial>
    <visual>
      <origin
        xyz="0 0 0"
        rpy="0 0 0" />
      <geometry>
        <mesh
          filename="package://arm/meshes/link6.STL" />
      </geometry>
      <material
        name="">
        <color
          rgba="0.666666666666667 0.698039215686274 0.768627450980392 1" />
      </material>
    </visual>
    <collision>
      <origin
        xyz="0 0 0"
        rpy="0 0 0" />
      <geometry>
        <mesh
          filename="package://arm/meshes/link6.STL" />
      </geometry>
    </collision>
  </link>
  <joint
    name="joint6"
    type="continuous">
    <origin
      xyz="0 0 0.0619999999999991"
      rpy="1.00343299394738 1.57079631189374 1.00343299394738" />
    <parent
      link="link5" />
    <child
      link="link6" />
    <axis
      xyz="0 0 0" />
  </joint>
  <link
    name="link7">
    <inertial>
      <origin
        xyz="-0.000171695716224329 -0.0477938544830668 -0.0357274171480665"
        rpy="0 0 0" />
      <mass
        value="0.0459845756601323" />
      <inertia
        ixx="6.09315616899348E-05"
        ixy="-1.06736207403593E-07"
        ixz="-4.51740345701921E-08"
        iyy="1.95971154056263E-05"
        iyz="-2.31066868313527E-05"
        izz="4.38592111632923E-05" />
    </inertial>
    <visual>
      <origin
        xyz="0 0 0"
        rpy="0 0 0" />
      <geometry>
        <mesh
          filename="package://arm/meshes/link7.STL" />
      </geometry>
      <material
        name="">
        <color
          rgba="0.666666666666667 0.698039215686274 0.768627450980392 1" />
      </material>
    </visual>
    <collision>
      <origin
        xyz="0 0 0"
        rpy="0 0 0" />
      <geometry>
        <mesh
          filename="package://arm/meshes/link7.STL" />
      </geometry>
    </collision>
  </link>
  <joint
    name="joint7"
    type="continuous">
    <origin
      xyz="-0.0236317279836453 0 0.0401317279836453"
      rpy="-0.528498821446243 0 -1.5707963267949" />
    <parent
      link="link6" />
    <child
      link="link7" />
    <axis
      xyz="1 0 0" />
  </joint>
  <link
    name="link8">
    <inertial>
      <origin
        xyz="-0.000171695716225106 -0.0477938544830668 -0.0357274171480664"
        rpy="0 0 0" />
      <mass
        value="0.0459845756601324" />
      <inertia
        ixx="6.0931561689935E-05"
        ixy="-1.06736207403785E-07"
        ixz="-4.51740345702874E-08"
        iyy="1.95971154056263E-05"
        iyz="-2.31066868313527E-05"
        izz="4.38592111632925E-05" />
    </inertial>
    <visual>
      <origin
        xyz="0 0 0"
        rpy="0 0 0" />
      <geometry>
        <mesh
          filename="package://arm/meshes/link8.STL" />
      </geometry>
      <material
        name="">
        <color
          rgba="0.666666666666667 0.698039215686274 0.768627450980392 1" />
      </material>
    </visual>
    <collision>
      <origin
        xyz="0 0 0"
        rpy="0 0 0" />
      <geometry>
        <mesh
          filename="package://arm/meshes/link8.STL" />
      </geometry>
    </collision>
  </link>
  <joint
    name="joint8"
    type="continuous">
    <origin
      xyz="0 0.0404718479582238 -0.0693127108592614"
      rpy="2.08399271792142 0 -3.14159265358979" />
    <parent
      link="link6" />
    <child
      link="link8" />
    <axis
      xyz="1 0 0" />
  </joint>
</robot>