<?xml version="1.0" ?>
<robot name="Basic_Robot" xmlns:xacro="http://www.ros.org/wiki/xacro">

<xacro:include filename="$(find basic_robot_description)/urdf/materials.xacro" />
<xacro:include filename="$(find basic_robot_description)/urdf/Basic_Robot.trans" />
<xacro:include filename="$(find basic_robot_description)/urdf/Basic_Robot.gazebo" />
<link name="base_link">
  <collision>
    <origin xyz="0 0 0" rpy="0 0 0"/>
    <geometry>
      <mesh filename="package://basic_robot_description/meshes/base_link.stl" />
    </geometry>
  </collision>
  <inertial>
    <origin xyz="0.057552808771839256 -0.00028843506105640903 -0.03489403146527645" rpy="0 0 0"/>
    <mass value="0.4424914005445932"/>
    <inertia ixx="0.000128" iyy="0.00046" izz="0.000341" ixy="2e-06" iyz="0.0" ixz="-0.0"/>
  </inertial>
  <visual>
    <origin xyz="0 0 0" rpy="0 0 0"/>
    <geometry>
      <mesh filename="package://basic_robot_description/meshes/base_link.stl" />
    </geometry>
    <material name="silver"/>
  </visual>
 
</link>

<link name="right_wheel_1">
  <collision>
    <origin xyz="-0.020071 0.005294 0.069776" rpy="0 0 0"/>
    <geometry>
      <mesh filename="package://basic_robot_description/meshes/right_wheel_1.stl" />
    </geometry>
  </collision>
  <inertial>
    <origin xyz="-0.005035675930104481 0.005146759319128036 0.003460302669957699" rpy="0 0 0"/>
    <mass value="0.015522874373267303"/>
    <inertia ixx="1e-06" iyy="1e-06" izz="2e-06" ixy="0.0" iyz="-0.0" ixz="0.0"/>
  </inertial>
  <visual>
    <origin xyz="-0.020071 0.005294 0.069776" rpy="0 0 0"/>
    <geometry>
      <mesh filename="package://basic_robot_description/meshes/right_wheel_1.stl" />
    </geometry>
    <material name="silver"/>
  </visual>
  
</link>

<link name="left_wheel_1">
  <collision>
    <origin xyz="-0.020071 0.005294 0.009776" rpy="0 0 0"/>
    <geometry>
      <mesh filename="package://basic_robot_description/meshes/left_wheel_1.stl" />
    </geometry>
  </collision>
  <inertial>
    <origin xyz="-0.0050356759301044725 0.005146759319128006 0.0063155305519952114" rpy="0 0 0"/>
    <mass value="0.015522874373267314"/>
    <inertia ixx="1e-06" iyy="1e-06" izz="2e-06" ixy="0.0" iyz="-0.0" ixz="0.0"/>
  </inertial>
  <visual>
    <origin xyz="-0.020071 0.005294 0.009776" rpy="0 0 0"/>
    <geometry>
      <mesh filename="package://basic_robot_description/meshes/left_wheel_1.stl" />
    </geometry>
    <material name="silver"/>
  </visual>
  
</link>

<joint name="Revolute 1" type="continuous">
  <origin xyz="0.020071 -0.005294 -0.069776" rpy="0 0 0"/>
  <parent link="base_link"/>
  <child link="right_wheel_1"/>
  <axis xyz="-0.0 0.0 -1.0"/>
</joint>

<joint name="Revolute 2" type="continuous">
  <origin xyz="0.020071 -0.005294 -0.009776" rpy="0 0 0"/>
  <parent link="base_link"/>
  <child link="left_wheel_1"/>
  <axis xyz="0.0 -0.0 1.0"/>
</joint>

</robot>
